[2023-07-09T08:02:27.992+0000] {taskinstance.py:1103} INFO - Dependencies all met for dep_context=non-requeueable deps ti=<TaskInstance: etl_dag.transform_data manual__2023-07-09T08:02:21.722273+00:00 [queued]>
[2023-07-09T08:02:28.015+0000] {taskinstance.py:1103} INFO - Dependencies all met for dep_context=requeueable deps ti=<TaskInstance: etl_dag.transform_data manual__2023-07-09T08:02:21.722273+00:00 [queued]>
[2023-07-09T08:02:28.038+0000] {taskinstance.py:1308} INFO - Starting attempt 1 of 1
[2023-07-09T08:02:28.068+0000] {taskinstance.py:1327} INFO - Executing <Task(PythonOperator): transform_data> on 2023-07-09 08:02:21.722273+00:00
[2023-07-09T08:02:28.076+0000] {standard_task_runner.py:57} INFO - Started process 1840 to run task
[2023-07-09T08:02:28.079+0000] {standard_task_runner.py:84} INFO - Running: ['***', 'tasks', 'run', 'etl_dag', 'transform_data', 'manual__2023-07-09T08:02:21.722273+00:00', '--job-id', '66', '--raw', '--subdir', 'DAGS_FOLDER/test.py', '--cfg-path', '/tmp/tmpioujk4q1']
[2023-07-09T08:02:28.080+0000] {standard_task_runner.py:85} INFO - Job 66: Subtask transform_data
[2023-07-09T08:02:28.134+0000] {task_command.py:410} INFO - Running <TaskInstance: etl_dag.transform_data manual__2023-07-09T08:02:21.722273+00:00 [running]> on host 5865fe7b5e5b
[2023-07-09T08:02:28.385+0000] {taskinstance.py:1547} INFO - Exporting env vars: AIRFLOW_CTX_DAG_OWNER='***' AIRFLOW_CTX_DAG_ID='etl_dag' AIRFLOW_CTX_TASK_ID='transform_data' AIRFLOW_CTX_EXECUTION_DATE='2023-07-09T08:02:21.722273+00:00' AIRFLOW_CTX_TRY_NUMBER='1' AIRFLOW_CTX_DAG_RUN_ID='manual__2023-07-09T08:02:21.722273+00:00'
[2023-07-09T08:02:28.389+0000] {taskinstance.py:1824} ERROR - Task failed with exception
Traceback (most recent call last):
  File "/home/airflow/.local/lib/python3.7/site-packages/airflow/operators/python.py", line 181, in execute
    return_value = self.execute_callable()
  File "/home/airflow/.local/lib/python3.7/site-packages/airflow/operators/python.py", line 198, in execute_callable
    return self.python_callable(*self.op_args, **self.op_kwargs)
  File "/opt/airflow/dags/test.py", line 21, in transform
    df['YearStart'] = datetime.strptime(str(df['YearStart']), '%Y')
  File "/usr/local/lib/python3.7/_strptime.py", line 577, in _strptime_datetime
    tt, fraction, gmtoff_fraction = _strptime(data_string, format)
  File "/usr/local/lib/python3.7/_strptime.py", line 359, in _strptime
    (data_string, format))
ValueError: time data '0     2014\n1     2018\n2     2018\n3     2017\n4     2010\n5     2015\n6     2013\n7     2013\n8     2017\n9     2010\n10    2016\n11    2014\n12    2015\n13    2016\n14    2020\n15    2012\n16    2015\n17    2018\n18    2017\nName: YearStart, dtype: int64' does not match format '%Y'
[2023-07-09T08:02:28.404+0000] {taskinstance.py:1350} INFO - Marking task as FAILED. dag_id=etl_dag, task_id=transform_data, execution_date=20230709T080221, start_date=20230709T080227, end_date=20230709T080228
[2023-07-09T08:02:28.422+0000] {standard_task_runner.py:109} ERROR - Failed to execute job 66 for task transform_data (time data '0     2014\n1     2018\n2     2018\n3     2017\n4     2010\n5     2015\n6     2013\n7     2013\n8     2017\n9     2010\n10    2016\n11    2014\n12    2015\n13    2016\n14    2020\n15    2012\n16    2015\n17    2018\n18    2017\nName: YearStart, dtype: int64' does not match format '%Y'; 1840)
[2023-07-09T08:02:28.452+0000] {local_task_job_runner.py:225} INFO - Task exited with return code 1
[2023-07-09T08:02:28.487+0000] {taskinstance.py:2653} INFO - 0 downstream tasks scheduled from follow-on schedule check
