[2023-07-09T06:53:48.537+0000] {taskinstance.py:1103} INFO - Dependencies all met for dep_context=non-requeueable deps ti=<TaskInstance: etl_dag.apply_pca manual__2023-07-09T06:53:41.625443+00:00 [queued]>
[2023-07-09T06:53:48.549+0000] {taskinstance.py:1103} INFO - Dependencies all met for dep_context=requeueable deps ti=<TaskInstance: etl_dag.apply_pca manual__2023-07-09T06:53:41.625443+00:00 [queued]>
[2023-07-09T06:53:48.550+0000] {taskinstance.py:1308} INFO - Starting attempt 1 of 1
[2023-07-09T06:53:48.570+0000] {taskinstance.py:1327} INFO - Executing <Task(PythonOperator): apply_pca> on 2023-07-09 06:53:41.625443+00:00
[2023-07-09T06:53:48.577+0000] {standard_task_runner.py:57} INFO - Started process 525 to run task
[2023-07-09T06:53:48.580+0000] {standard_task_runner.py:84} INFO - Running: ['***', 'tasks', 'run', 'etl_dag', 'apply_pca', 'manual__2023-07-09T06:53:41.625443+00:00', '--job-id', '46', '--raw', '--subdir', 'DAGS_FOLDER/test.py', '--cfg-path', '/tmp/tmph2uop6hj']
[2023-07-09T06:53:48.581+0000] {standard_task_runner.py:85} INFO - Job 46: Subtask apply_pca
[2023-07-09T06:53:48.631+0000] {task_command.py:410} INFO - Running <TaskInstance: etl_dag.apply_pca manual__2023-07-09T06:53:41.625443+00:00 [running]> on host 5865fe7b5e5b
[2023-07-09T06:53:48.846+0000] {taskinstance.py:1547} INFO - Exporting env vars: AIRFLOW_CTX_DAG_OWNER='***' AIRFLOW_CTX_DAG_ID='etl_dag' AIRFLOW_CTX_TASK_ID='apply_pca' AIRFLOW_CTX_EXECUTION_DATE='2023-07-09T06:53:41.625443+00:00' AIRFLOW_CTX_TRY_NUMBER='1' AIRFLOW_CTX_DAG_RUN_ID='manual__2023-07-09T06:53:41.625443+00:00'
[2023-07-09T06:53:48.849+0000] {taskinstance.py:1824} ERROR - Task failed with exception
Traceback (most recent call last):
  File "/home/airflow/.local/lib/python3.7/site-packages/airflow/operators/python.py", line 181, in execute
    return_value = self.execute_callable()
  File "/home/airflow/.local/lib/python3.7/site-packages/airflow/operators/python.py", line 198, in execute_callable
    return self.python_callable(*self.op_args, **self.op_kwargs)
  File "/opt/airflow/dags/test.py", line 28, in apply_pca
    X = df[features]
  File "/home/airflow/.local/lib/python3.7/site-packages/pandas/core/frame.py", line 3464, in __getitem__
    indexer = self.loc._get_listlike_indexer(key, axis=1)[1]
  File "/home/airflow/.local/lib/python3.7/site-packages/pandas/core/indexing.py", line 1314, in _get_listlike_indexer
    self._validate_read_indexer(keyarr, indexer, axis)
  File "/home/airflow/.local/lib/python3.7/site-packages/pandas/core/indexing.py", line 1374, in _validate_read_indexer
    raise KeyError(f"None of [{key}] are in the [{axis_name}]")
KeyError: "None of [Index(['Latitude', 'Longitude'], dtype='object')] are in the [columns]"
[2023-07-09T06:53:48.867+0000] {taskinstance.py:1350} INFO - Marking task as FAILED. dag_id=etl_dag, task_id=apply_pca, execution_date=20230709T065341, start_date=20230709T065348, end_date=20230709T065348
[2023-07-09T06:53:48.889+0000] {standard_task_runner.py:109} ERROR - Failed to execute job 46 for task apply_pca ("None of [Index(['Latitude', 'Longitude'], dtype='object')] are in the [columns]"; 525)
[2023-07-09T06:53:48.913+0000] {local_task_job_runner.py:225} INFO - Task exited with return code 1
[2023-07-09T06:53:48.946+0000] {taskinstance.py:2653} INFO - 0 downstream tasks scheduled from follow-on schedule check
