[2023-07-09T06:47:46.383+0000] {taskinstance.py:1103} INFO - Dependencies all met for dep_context=non-requeueable deps ti=<TaskInstance: etl_dag.load_data manual__2023-07-09T06:47:39.297456+00:00 [queued]>
[2023-07-09T06:47:46.394+0000] {taskinstance.py:1103} INFO - Dependencies all met for dep_context=requeueable deps ti=<TaskInstance: etl_dag.load_data manual__2023-07-09T06:47:39.297456+00:00 [queued]>
[2023-07-09T06:47:46.396+0000] {taskinstance.py:1308} INFO - Starting attempt 1 of 1
[2023-07-09T06:47:46.419+0000] {taskinstance.py:1327} INFO - Executing <Task(PythonOperator): load_data> on 2023-07-09 06:47:39.297456+00:00
[2023-07-09T06:47:46.429+0000] {standard_task_runner.py:57} INFO - Started process 366 to run task
[2023-07-09T06:47:46.432+0000] {standard_task_runner.py:84} INFO - Running: ['***', 'tasks', 'run', 'etl_dag', 'load_data', 'manual__2023-07-09T06:47:39.297456+00:00', '--job-id', '40', '--raw', '--subdir', 'DAGS_FOLDER/test.py', '--cfg-path', '/tmp/tmpzf8p7ye9']
[2023-07-09T06:47:46.433+0000] {standard_task_runner.py:85} INFO - Job 40: Subtask load_data
[2023-07-09T06:47:46.499+0000] {task_command.py:410} INFO - Running <TaskInstance: etl_dag.load_data manual__2023-07-09T06:47:39.297456+00:00 [running]> on host 5865fe7b5e5b
[2023-07-09T06:47:46.728+0000] {taskinstance.py:1547} INFO - Exporting env vars: AIRFLOW_CTX_DAG_OWNER='***' AIRFLOW_CTX_DAG_ID='etl_dag' AIRFLOW_CTX_TASK_ID='load_data' AIRFLOW_CTX_EXECUTION_DATE='2023-07-09T06:47:39.297456+00:00' AIRFLOW_CTX_TRY_NUMBER='1' AIRFLOW_CTX_DAG_RUN_ID='manual__2023-07-09T06:47:39.297456+00:00'
[2023-07-09T06:47:46.752+0000] {base.py:73} INFO - Using connection ID 'testsql' for task execution.
[2023-07-09T06:47:46.753+0000] {taskinstance.py:1824} ERROR - Task failed with exception
Traceback (most recent call last):
  File "/home/airflow/.local/lib/python3.7/site-packages/airflow/operators/python.py", line 181, in execute
    return_value = self.execute_callable()
  File "/home/airflow/.local/lib/python3.7/site-packages/airflow/operators/python.py", line 198, in execute_callable
    return self.python_callable(*self.op_args, **self.op_kwargs)
  File "/opt/airflow/dags/test.py", line 32, in load
    df.to_sql('mytable', engine, if_exists='replace', index=False)
  File "/home/airflow/.local/lib/python3.7/site-packages/pandas/core/generic.py", line 2882, in to_sql
    method=method,
  File "/home/airflow/.local/lib/python3.7/site-packages/pandas/io/sql.py", line 728, in to_sql
    **engine_kwargs,
  File "/home/airflow/.local/lib/python3.7/site-packages/pandas/io/sql.py", line 1758, in to_sql
    dtype=dtype,
  File "/home/airflow/.local/lib/python3.7/site-packages/pandas/io/sql.py", line 1650, in prep_table
    table.create()
  File "/home/airflow/.local/lib/python3.7/site-packages/pandas/io/sql.py", line 856, in create
    if self.exists():
  File "/home/airflow/.local/lib/python3.7/site-packages/pandas/io/sql.py", line 840, in exists
    return self.pd_sql.has_table(self.name, self.schema)
  File "/home/airflow/.local/lib/python3.7/site-packages/pandas/io/sql.py", line 1783, in has_table
    insp = sa.inspect(self.connectable)
  File "/home/airflow/.local/lib/python3.7/site-packages/sqlalchemy/inspection.py", line 64, in inspect
    ret = reg(subject)
  File "/home/airflow/.local/lib/python3.7/site-packages/sqlalchemy/engine/reflection.py", line 182, in _engine_insp
    return Inspector._construct(Inspector._init_engine, bind)
  File "/home/airflow/.local/lib/python3.7/site-packages/sqlalchemy/engine/reflection.py", line 117, in _construct
    init(self, bind)
  File "/home/airflow/.local/lib/python3.7/site-packages/sqlalchemy/engine/reflection.py", line 128, in _init_engine
    engine.connect().close()
  File "/home/airflow/.local/lib/python3.7/site-packages/sqlalchemy/engine/base.py", line 3320, in connect
    return self._connection_cls(self, close_with_result=close_with_result)
  File "/home/airflow/.local/lib/python3.7/site-packages/sqlalchemy/engine/base.py", line 96, in __init__
    else engine.raw_connection()
  File "/home/airflow/.local/lib/python3.7/site-packages/sqlalchemy/engine/base.py", line 3399, in raw_connection
    return self._wrap_pool_connect(self.pool.connect, _connection)
  File "/home/airflow/.local/lib/python3.7/site-packages/sqlalchemy/engine/base.py", line 3366, in _wrap_pool_connect
    return fn()
  File "/home/airflow/.local/lib/python3.7/site-packages/sqlalchemy/pool/base.py", line 327, in connect
    return _ConnectionFairy._checkout(self)
  File "/home/airflow/.local/lib/python3.7/site-packages/sqlalchemy/pool/base.py", line 894, in _checkout
    fairy = _ConnectionRecord.checkout(pool)
  File "/home/airflow/.local/lib/python3.7/site-packages/sqlalchemy/pool/base.py", line 493, in checkout
    rec = pool._do_get()
  File "/home/airflow/.local/lib/python3.7/site-packages/sqlalchemy/pool/impl.py", line 146, in _do_get
    self._dec_overflow()
  File "/home/airflow/.local/lib/python3.7/site-packages/sqlalchemy/util/langhelpers.py", line 72, in __exit__
    with_traceback=exc_tb,
  File "/home/airflow/.local/lib/python3.7/site-packages/sqlalchemy/util/compat.py", line 211, in raise_
    raise exception
  File "/home/airflow/.local/lib/python3.7/site-packages/sqlalchemy/pool/impl.py", line 143, in _do_get
    return self._create_connection()
  File "/home/airflow/.local/lib/python3.7/site-packages/sqlalchemy/pool/base.py", line 273, in _create_connection
    return _ConnectionRecord(self)
  File "/home/airflow/.local/lib/python3.7/site-packages/sqlalchemy/pool/base.py", line 388, in __init__
    self.__connect()
  File "/home/airflow/.local/lib/python3.7/site-packages/sqlalchemy/pool/base.py", line 704, in __connect
    )._exec_w_sync_on_first_run(self.dbapi_connection, self)
  File "/home/airflow/.local/lib/python3.7/site-packages/sqlalchemy/event/attr.py", line 320, in _exec_w_sync_on_first_run
    self(*args, **kw)
  File "/home/airflow/.local/lib/python3.7/site-packages/sqlalchemy/event/attr.py", line 334, in __call__
    fn(*args, **kw)
  File "/home/airflow/.local/lib/python3.7/site-packages/sqlalchemy/engine/create.py", line 654, in on_connect
    do_on_connect(dbapi_connection)
  File "/home/airflow/.local/lib/python3.7/site-packages/sqlalchemy/dialects/mysql/mysqldb.py", line 159, in on_connect
    charset_name = conn.character_set_name()
AttributeError: 'Engine' object has no attribute 'character_set_name'
[2023-07-09T06:47:46.774+0000] {taskinstance.py:1350} INFO - Marking task as FAILED. dag_id=etl_dag, task_id=load_data, execution_date=20230709T064739, start_date=20230709T064746, end_date=20230709T064746
[2023-07-09T06:47:46.792+0000] {standard_task_runner.py:109} ERROR - Failed to execute job 40 for task load_data ('Engine' object has no attribute 'character_set_name'; 366)
[2023-07-09T06:47:46.805+0000] {local_task_job_runner.py:225} INFO - Task exited with return code 1
[2023-07-09T06:47:46.827+0000] {taskinstance.py:2653} INFO - 0 downstream tasks scheduled from follow-on schedule check
