[2023-07-09T06:57:12.404+0000] {taskinstance.py:1103} INFO - Dependencies all met for dep_context=non-requeueable deps ti=<TaskInstance: etl_dag.transform_data manual__2023-07-09T06:57:06.454615+00:00 [queued]>
[2023-07-09T06:57:12.422+0000] {taskinstance.py:1103} INFO - Dependencies all met for dep_context=requeueable deps ti=<TaskInstance: etl_dag.transform_data manual__2023-07-09T06:57:06.454615+00:00 [queued]>
[2023-07-09T06:57:12.423+0000] {taskinstance.py:1308} INFO - Starting attempt 1 of 1
[2023-07-09T06:57:12.453+0000] {taskinstance.py:1327} INFO - Executing <Task(PythonOperator): transform_data> on 2023-07-09 06:57:06.454615+00:00
[2023-07-09T06:57:12.461+0000] {standard_task_runner.py:57} INFO - Started process 616 to run task
[2023-07-09T06:57:12.465+0000] {standard_task_runner.py:84} INFO - Running: ['***', 'tasks', 'run', 'etl_dag', 'transform_data', 'manual__2023-07-09T06:57:06.454615+00:00', '--job-id', '50', '--raw', '--subdir', 'DAGS_FOLDER/test.py', '--cfg-path', '/tmp/tmp4v_pngv_']
[2023-07-09T06:57:12.466+0000] {standard_task_runner.py:85} INFO - Job 50: Subtask transform_data
[2023-07-09T06:57:12.534+0000] {task_command.py:410} INFO - Running <TaskInstance: etl_dag.transform_data manual__2023-07-09T06:57:06.454615+00:00 [running]> on host 5865fe7b5e5b
[2023-07-09T06:57:12.788+0000] {taskinstance.py:1547} INFO - Exporting env vars: AIRFLOW_CTX_DAG_OWNER='***' AIRFLOW_CTX_DAG_ID='etl_dag' AIRFLOW_CTX_TASK_ID='transform_data' AIRFLOW_CTX_EXECUTION_DATE='2023-07-09T06:57:06.454615+00:00' AIRFLOW_CTX_TRY_NUMBER='1' AIRFLOW_CTX_DAG_RUN_ID='manual__2023-07-09T06:57:06.454615+00:00'
[2023-07-09T06:57:12.794+0000] {taskinstance.py:1824} ERROR - Task failed with exception
Traceback (most recent call last):
  File "/home/airflow/.local/lib/python3.7/site-packages/pandas/core/indexes/base.py", line 3361, in get_loc
    return self._engine.get_loc(casted_key)
  File "pandas/_libs/index.pyx", line 76, in pandas._libs.index.IndexEngine.get_loc
  File "pandas/_libs/index.pyx", line 108, in pandas._libs.index.IndexEngine.get_loc
  File "pandas/_libs/hashtable_class_helper.pxi", line 5198, in pandas._libs.hashtable.PyObjectHashTable.get_item
  File "pandas/_libs/hashtable_class_helper.pxi", line 5206, in pandas._libs.hashtable.PyObjectHashTable.get_item
KeyError: '_id'

The above exception was the direct cause of the following exception:

Traceback (most recent call last):
  File "/home/airflow/.local/lib/python3.7/site-packages/airflow/operators/python.py", line 181, in execute
    return_value = self.execute_callable()
  File "/home/airflow/.local/lib/python3.7/site-packages/airflow/operators/python.py", line 198, in execute_callable
    return self.python_callable(*self.op_args, **self.op_kwargs)
  File "/opt/airflow/dags/test.py", line 21, in transform
    df['seguir'] = df["_id"]["$oid"]
  File "/home/airflow/.local/lib/python3.7/site-packages/pandas/core/frame.py", line 3458, in __getitem__
    indexer = self.columns.get_loc(key)
  File "/home/airflow/.local/lib/python3.7/site-packages/pandas/core/indexes/base.py", line 3363, in get_loc
    raise KeyError(key) from err
KeyError: '_id'
[2023-07-09T06:57:12.814+0000] {taskinstance.py:1350} INFO - Marking task as FAILED. dag_id=etl_dag, task_id=transform_data, execution_date=20230709T065706, start_date=20230709T065712, end_date=20230709T065712
[2023-07-09T06:57:12.831+0000] {standard_task_runner.py:109} ERROR - Failed to execute job 50 for task transform_data ('_id'; 616)
[2023-07-09T06:57:12.877+0000] {local_task_job_runner.py:225} INFO - Task exited with return code 1
[2023-07-09T06:57:12.910+0000] {taskinstance.py:2653} INFO - 0 downstream tasks scheduled from follow-on schedule check
