[2023-07-09T06:42:21.035+0000] {taskinstance.py:1103} INFO - Dependencies all met for dep_context=non-requeueable deps ti=<TaskInstance: etl_dag.transform_data manual__2023-07-09T06:42:15.734529+00:00 [queued]>
[2023-07-09T06:42:21.049+0000] {taskinstance.py:1103} INFO - Dependencies all met for dep_context=requeueable deps ti=<TaskInstance: etl_dag.transform_data manual__2023-07-09T06:42:15.734529+00:00 [queued]>
[2023-07-09T06:42:21.050+0000] {taskinstance.py:1308} INFO - Starting attempt 1 of 1
[2023-07-09T06:42:21.070+0000] {taskinstance.py:1327} INFO - Executing <Task(PythonOperator): transform_data> on 2023-07-09 06:42:15.734529+00:00
[2023-07-09T06:42:21.076+0000] {standard_task_runner.py:57} INFO - Started process 218 to run task
[2023-07-09T06:42:21.079+0000] {standard_task_runner.py:84} INFO - Running: ['***', 'tasks', 'run', 'etl_dag', 'transform_data', 'manual__2023-07-09T06:42:15.734529+00:00', '--job-id', '34', '--raw', '--subdir', 'DAGS_FOLDER/test.py', '--cfg-path', '/tmp/tmp0ui16vdx']
[2023-07-09T06:42:21.080+0000] {standard_task_runner.py:85} INFO - Job 34: Subtask transform_data
[2023-07-09T06:42:21.129+0000] {task_command.py:410} INFO - Running <TaskInstance: etl_dag.transform_data manual__2023-07-09T06:42:15.734529+00:00 [running]> on host 5865fe7b5e5b
[2023-07-09T06:42:21.305+0000] {taskinstance.py:1547} INFO - Exporting env vars: AIRFLOW_CTX_DAG_OWNER='***' AIRFLOW_CTX_DAG_ID='etl_dag' AIRFLOW_CTX_TASK_ID='transform_data' AIRFLOW_CTX_EXECUTION_DATE='2023-07-09T06:42:15.734529+00:00' AIRFLOW_CTX_TRY_NUMBER='1' AIRFLOW_CTX_DAG_RUN_ID='manual__2023-07-09T06:42:15.734529+00:00'
[2023-07-09T06:42:21.307+0000] {taskinstance.py:1824} ERROR - Task failed with exception
Traceback (most recent call last):
  File "/home/airflow/.local/lib/python3.7/site-packages/airflow/operators/python.py", line 181, in execute
    return_value = self.execute_callable()
  File "/home/airflow/.local/lib/python3.7/site-packages/airflow/operators/python.py", line 198, in execute_callable
    return self.python_callable(*self.op_args, **self.op_kwargs)
  File "/opt/airflow/dags/test.py", line 21, in transform
    float, geo_location.strip('POINT ()').split())
  File "/home/airflow/.local/lib/python3.7/site-packages/pandas/core/generic.py", line 5487, in __getattr__
    return object.__getattribute__(self, name)
AttributeError: 'Series' object has no attribute 'strip'
[2023-07-09T06:42:21.322+0000] {taskinstance.py:1350} INFO - Marking task as FAILED. dag_id=etl_dag, task_id=transform_data, execution_date=20230709T064215, start_date=20230709T064221, end_date=20230709T064221
[2023-07-09T06:42:21.336+0000] {standard_task_runner.py:109} ERROR - Failed to execute job 34 for task transform_data ('Series' object has no attribute 'strip'; 218)
[2023-07-09T06:42:21.371+0000] {local_task_job_runner.py:225} INFO - Task exited with return code 1
[2023-07-09T06:42:21.407+0000] {taskinstance.py:2653} INFO - 0 downstream tasks scheduled from follow-on schedule check
