[2023-07-09T06:40:56.604+0000] {taskinstance.py:1103} INFO - Dependencies all met for dep_context=non-requeueable deps ti=<TaskInstance: etl_dag.transform_data manual__2023-07-09T06:40:51.083847+00:00 [queued]>
[2023-07-09T06:40:56.615+0000] {taskinstance.py:1103} INFO - Dependencies all met for dep_context=requeueable deps ti=<TaskInstance: etl_dag.transform_data manual__2023-07-09T06:40:51.083847+00:00 [queued]>
[2023-07-09T06:40:56.616+0000] {taskinstance.py:1308} INFO - Starting attempt 1 of 1
[2023-07-09T06:40:56.635+0000] {taskinstance.py:1327} INFO - Executing <Task(PythonOperator): transform_data> on 2023-07-09 06:40:51.083847+00:00
[2023-07-09T06:40:56.641+0000] {standard_task_runner.py:57} INFO - Started process 176 to run task
[2023-07-09T06:40:56.645+0000] {standard_task_runner.py:84} INFO - Running: ['***', 'tasks', 'run', 'etl_dag', 'transform_data', 'manual__2023-07-09T06:40:51.083847+00:00', '--job-id', '30', '--raw', '--subdir', 'DAGS_FOLDER/test.py', '--cfg-path', '/tmp/tmpibs7mm40']
[2023-07-09T06:40:56.645+0000] {standard_task_runner.py:85} INFO - Job 30: Subtask transform_data
[2023-07-09T06:40:56.696+0000] {task_command.py:410} INFO - Running <TaskInstance: etl_dag.transform_data manual__2023-07-09T06:40:51.083847+00:00 [running]> on host 5865fe7b5e5b
[2023-07-09T06:40:56.887+0000] {taskinstance.py:1547} INFO - Exporting env vars: AIRFLOW_CTX_DAG_OWNER='***' AIRFLOW_CTX_DAG_ID='etl_dag' AIRFLOW_CTX_TASK_ID='transform_data' AIRFLOW_CTX_EXECUTION_DATE='2023-07-09T06:40:51.083847+00:00' AIRFLOW_CTX_TRY_NUMBER='1' AIRFLOW_CTX_DAG_RUN_ID='manual__2023-07-09T06:40:51.083847+00:00'
[2023-07-09T06:40:56.889+0000] {taskinstance.py:1824} ERROR - Task failed with exception
Traceback (most recent call last):
  File "/home/airflow/.local/lib/python3.7/site-packages/airflow/operators/python.py", line 181, in execute
    return_value = self.execute_callable()
  File "/home/airflow/.local/lib/python3.7/site-packages/airflow/operators/python.py", line 198, in execute_callable
    return self.python_callable(*self.op_args, **self.op_kwargs)
  File "/opt/airflow/dags/test.py", line 20, in transform
    float, geo_location.strip('POINT ()').split())
  File "/home/airflow/.local/lib/python3.7/site-packages/pandas/core/generic.py", line 5487, in __getattr__
    return object.__getattribute__(self, name)
AttributeError: 'Series' object has no attribute 'strip'
[2023-07-09T06:40:56.901+0000] {taskinstance.py:1350} INFO - Marking task as FAILED. dag_id=etl_dag, task_id=transform_data, execution_date=20230709T064051, start_date=20230709T064056, end_date=20230709T064056
[2023-07-09T06:40:56.917+0000] {standard_task_runner.py:109} ERROR - Failed to execute job 30 for task transform_data ('Series' object has no attribute 'strip'; 176)
[2023-07-09T06:40:56.937+0000] {local_task_job_runner.py:225} INFO - Task exited with return code 1
[2023-07-09T06:40:56.961+0000] {taskinstance.py:2653} INFO - 0 downstream tasks scheduled from follow-on schedule check
